return { { ["x"] = 0, ["meta"] = { ["fields"] = {  }, ["inventory"] = {  } }, ["param2"] = 0, ["y"] = 2, ["param1"] = 15, ["z"] = 0, ["name"] = "air" }, { ["x"] = 0, ["meta"] = { ["fields"] = {  }, ["inventory"] = {  } }, ["param2"] = 0, ["y"] = 2, ["param1"] = 15, ["z"] = 1, ["name"] = "air" }, { ["x"] = 0, ["meta"] = { ["fields"] = {  }, ["inventory"] = {  } }, ["param2"] = 0, ["y"] = 2, ["param1"] = 15, ["z"] = 2, ["name"] = "air" }, { ["x"] = 0, ["meta"] = { ["fields"] = {  }, ["inventory"] = {  } }, ["param2"] = 0, ["y"] = 2, ["param1"] = 15, ["z"] = 3, ["name"] = "air" }, { ["x"] = 0, ["meta"] = { ["fields"] = {  }, ["inventory"] = {  } }, ["param2"] = 0, ["y"] = 2, ["param1"] = 15, ["z"] = 4, ["name"] = "air" }, { ["x"] = 0, ["meta"] = { ["fields"] = {  }, ["inventory"] = {  } }, ["param2"] = 0, ["y"] = 2, ["param1"] = 15, ["z"] = 5, ["name"] = "air" }, { ["x"] = 0, ["meta"] = { ["fields"] = {  }, ["inventory"] = {  } }, ["param2"] = 0, ["y"] = 2, ["param1"] = 15, ["z"] = 6, ["name"] = "air" }, { ["x"] = 0, ["meta"] = { ["fields"] = {  }, ["inventory"] = {  } }, ["param2"] = 0, ["y"] = 2, ["param1"] = 15, ["z"] = 7, ["name"] = "air" }, { ["x"] = 0, ["meta"] = { ["fields"] = {  }, ["inventory"] = {  } }, ["param2"] = 0, ["y"] = 2, ["param1"] = 15, ["z"] = 8, ["name"] = "air" }, { ["x"] = 0, ["meta"] = { ["fields"] = {  }, ["inventory"] = {  } }, ["param2"] = 0, ["y"] = 3, ["param1"] = 15, ["z"] = 0, ["name"] = "air" }, { ["x"] = 0, ["meta"] = { ["fields"] = {  }, ["inventory"] = {  } }, ["param2"] = 0, ["y"] = 3, ["param1"] = 15, ["z"] = 1, ["name"] = "air" }, { ["x"] = 0, ["meta"] = { ["fields"] = {  }, ["inventory"] = {  } }, ["param2"] = 0, ["y"] = 3, ["param1"] = 15, ["z"] = 2, ["name"] = "air" }, { ["x"] = 0, ["meta"] = { ["fields"] = {  }, ["inventory"] = {  } }, ["param2"] = 0, ["y"] = 3, ["param1"] = 15, ["z"] = 3, ["name"] = "air" }, { ["x"] = 0, ["meta"] = { ["fields"] = {  }, ["inventory"] = {  } }, ["param2"] = 0, ["y"] = 3, ["param1"] = 15, ["z"] = 4, ["name"] = "air" }, { ["x"] = 0, ["meta"] = { ["fields"] = {  }, ["inventory"] = {  } }, ["param2"] = 0, ["y"] = 3, ["param1"] = 15, ["z"] = 5, ["name"] = "air" }, { ["x"] = 0, ["meta"] = { ["fields"] = {  }, ["inventory"] = {  } }, ["param2"] = 0, ["y"] = 3, ["param1"] = 15, ["z"] = 6, ["name"] = "air" }, { ["x"] = 0, ["meta"] = { ["fields"] = {  }, ["inventory"] = {  } }, ["param2"] = 0, ["y"] = 3, ["param1"] = 15, ["z"] = 7, ["name"] = "air" }, { ["x"] = 0, ["meta"] = { ["fields"] = {  }, ["inventory"] = {  } }, ["param2"] = 0, ["y"] = 3, ["param1"] = 15, ["z"] = 8, ["name"] = "air" }, { ["x"] = 1, ["meta"] = { ["fields"] = {  }, ["inventory"] = {  } }, ["param2"] = 0, ["y"] = 0, ["param1"] = 0, ["z"] = 1, ["name"] = "default:dirt" }, { ["x"] = 1, ["meta"] = { ["fields"] = {  }, ["inventory"] = {  } }, ["param2"] = 0, ["y"] = 0, ["param1"] = 0, ["z"] = 2, ["name"] = "default:dirt" }, { ["x"] = 1, ["meta"] = { ["fields"] = {  }, ["inventory"] = {  } }, ["param2"] = 0, ["y"] = 0, ["param1"] = 0, ["z"] = 3, ["name"] = "default:dirt" }, { ["x"] = 1, ["meta"] = { ["fields"] = {  }, ["inventory"] = {  } }, ["param2"] = 0, ["y"] = 0, ["param1"] = 0, ["z"] = 4, ["name"] = "default:dirt" }, { ["x"] = 1, ["meta"] = { ["fields"] = {  }, ["inventory"] = {  } }, ["param2"] = 0, ["y"] = 0, ["param1"] = 0, ["z"] = 5, ["name"] = "default:dirt" }, { ["x"] = 1, ["meta"] = { ["fields"] = {  }, ["inventory"] = {  } }, ["param2"] = 0, ["y"] = 0, ["param1"] = 0, ["z"] = 6, ["name"] = "default:dirt" }, { ["x"] = 1, ["meta"] = { ["fields"] = {  }, ["inventory"] = {  } }, ["param2"] = 0, ["y"] = 0, ["param1"] = 0, ["z"] = 7, ["name"] = "default:dirt" }, { ["x"] = 1, ["meta"] = { ["fields"] = {  }, ["inventory"] = {  } }, ["param2"] = 0, ["y"] = 1, ["param1"] = 0, ["z"] = 1, ["name"] = "default:junglewood" }, { ["x"] = 1, ["meta"] = { ["fields"] = {  }, ["inventory"] = {  } }, ["param2"] = 0, ["y"] = 1, ["param1"] = 0, ["z"] = 2, ["name"] = "default:junglewood" }, { ["x"] = 1, ["meta"] = { ["fields"] = {  }, ["inventory"] = {  } }, ["param2"] = 0, ["y"] = 1, ["param1"] = 0, ["z"] = 3, ["name"] = "default:junglewood" }, { ["x"] = 1, ["meta"] = { ["fields"] = {  }, ["inventory"] = {  } }, ["param2"] = 0, ["y"] = 1, ["param1"] = 0, ["z"] = 4, ["name"] = "default:junglewood" }, { ["x"] = 1, ["meta"] = { ["fields"] = {  }, ["inventory"] = {  } }, ["param2"] = 0, ["y"] = 1, ["param1"] = 0, ["z"] = 5, ["name"] = "default:junglewood" }, { ["x"] = 1, ["meta"] = { ["fields"] = {  }, ["inventory"] = {  } }, ["param2"] = 0, ["y"] = 1, ["param1"] = 0, ["z"] = 6, ["name"] = "default:junglewood" }, { ["x"] = 1, ["meta"] = { ["fields"] = {  }, ["inventory"] = {  } }, ["param2"] = 0, ["y"] = 1, ["param1"] = 0, ["z"] = 7, ["name"] = "default:junglewood" }, { ["x"] = 1, ["meta"] = { ["fields"] = {  }, ["inventory"] = {  } }, ["param2"] = 0, ["y"] = 2, ["param1"] = 15, ["z"] = 0, ["name"] = "air" }, { ["x"] = 1, ["meta"] = { ["fields"] = {  }, ["inventory"] = {  } }, ["param2"] = 3, ["y"] = 2, ["param1"] = 13, ["z"] = 1, ["name"] = "default:fence_wood" }, { ["x"] = 1, ["meta"] = { ["fields"] = {  }, ["inventory"] = {  } }, ["param2"] = 3, ["y"] = 2, ["param1"] = 13, ["z"] = 2, ["name"] = "default:fence_wood" }, { ["x"] = 1, ["meta"] = { ["fields"] = {  }, ["inventory"] = {  } }, ["param2"] = 3, ["y"] = 2, ["param1"] = 13, ["z"] = 3, ["name"] = "default:fence_wood" }, { ["x"] = 1, ["meta"] = { ["fields"] = {  }, ["inventory"] = {  } }, ["param2"] = 3, ["y"] = 2, ["param1"] = 13, ["z"] = 4, ["name"] = "default:fence_wood" }, { ["x"] = 1, ["meta"] = { ["fields"] = {  }, ["inventory"] = {  } }, ["param2"] = 0, ["y"] = 2, ["param1"] = 13, ["z"] = 5, ["name"] = "default:fence_wood" }, { ["x"] = 1, ["meta"] = { ["fields"] = {  }, ["inventory"] = {  } }, ["param2"] = 3, ["y"] = 2, ["param1"] = 13, ["z"] = 6, ["name"] = "default:fence_wood" }, { ["x"] = 1, ["meta"] = { ["fields"] = {  }, ["inventory"] = {  } }, ["param2"] = 3, ["y"] = 2, ["param1"] = 13, ["z"] = 7, ["name"] = "default:fence_wood" }, { ["x"] = 1, ["meta"] = { ["fields"] = {  }, ["inventory"] = {  } }, ["param2"] = 0, ["y"] = 2, ["param1"] = 15, ["z"] = 8, ["name"] = "air" }, { ["x"] = 1, ["meta"] = { ["fields"] = {  }, ["inventory"] = {  } }, ["param2"] = 0, ["y"] = 3, ["param1"] = 15, ["z"] = 0, ["name"] = "air" }, { ["x"] = 1, ["meta"] = { ["fields"] = {  }, ["inventory"] = {  } }, ["param2"] = 0, ["y"] = 3, ["param1"] = 15, ["z"] = 1, ["name"] = "air" }, { ["x"] = 1, ["meta"] = { ["fields"] = {  }, ["inventory"] = {  } }, ["param2"] = 0, ["y"] = 3, ["param1"] = 15, ["z"] = 2, ["name"] = "air" }, { ["x"] = 1, ["meta"] = { ["fields"] = {  }, ["inventory"] = {  } }, ["param2"] = 0, ["y"] = 3, ["param1"] = 15, ["z"] = 3, ["name"] = "air" }, { ["x"] = 1, ["meta"] = { ["fields"] = {  }, ["inventory"] = {  } }, ["param2"] = 0, ["y"] = 3, ["param1"] = 15, ["z"] = 4, ["name"] = "air" }, { ["x"] = 1, ["meta"] = { ["fields"] = {  }, ["inventory"] = {  } }, ["param2"] = 0, ["y"] = 3, ["param1"] = 15, ["z"] = 5, ["name"] = "air" }, { ["x"] = 1, ["meta"] = { ["fields"] = {  }, ["inventory"] = {  } }, ["param2"] = 0, ["y"] = 3, ["param1"] = 15, ["z"] = 6, ["name"] = "air" }, { ["x"] = 1, ["meta"] = { ["fields"] = {  }, ["inventory"] = {  } }, ["param2"] = 0, ["y"] = 3, ["param1"] = 15, ["z"] = 7, ["name"] = "air" }, { ["x"] = 1, ["meta"] = { ["fields"] = {  }, ["inventory"] = {  } }, ["param2"] = 0, ["y"] = 3, ["param1"] = 15, ["z"] = 8, ["name"] = "air" }, { ["x"] = 2, ["meta"] = { ["fields"] = {  }, ["inventory"] = {  } }, ["param2"] = 0, ["y"] = 0, ["param1"] = 0, ["z"] = 1, ["name"] = "default:dirt" }, { ["x"] = 2, ["meta"] = { ["fields"] = {  }, ["inventory"] = {  } }, ["param2"] = 0, ["y"] = 0, ["param1"] = 0, ["z"] = 2, ["name"] = "default:dirt" }, { ["x"] = 2, ["meta"] = { ["fields"] = {  }, ["inventory"] = {  } }, ["param2"] = 0, ["y"] = 0, ["param1"] = 0, ["z"] = 3, ["name"] = "default:dirt" }, { ["x"] = 2, ["meta"] = { ["fields"] = {  }, ["inventory"] = {  } }, ["param2"] = 0, ["y"] = 0, ["param1"] = 0, ["z"] = 4, ["name"] = "default:dirt" }, { ["x"] = 2, ["meta"] = { ["fields"] = {  }, ["inventory"] = {  } }, ["param2"] = 0, ["y"] = 0, ["param1"] = 0, ["z"] = 5, ["name"] = "default:dirt" }, { ["x"] = 2, ["meta"] = { ["fields"] = {  }, ["inventory"] = {  } }, ["param2"] = 0, ["y"] = 0, ["param1"] = 0, ["z"] = 6, ["name"] = "default:dirt" }, { ["x"] = 2, ["meta"] = { ["fields"] = {  }, ["inventory"] = {  } }, ["param2"] = 0, ["y"] = 0, ["param1"] = 0, ["z"] = 7, ["name"] = "default:dirt" }, { ["x"] = 2, ["meta"] = { ["fields"] = {  }, ["inventory"] = {  } }, ["param2"] = 0, ["y"] = 1, ["param1"] = 0, ["z"] = 1, ["name"] = "default:junglewood" }, { ["x"] = 2, ["meta"] = { ["fields"] = {  }, ["inventory"] = {  } }, ["param2"] = 0, ["y"] = 1, ["param1"] = 13, ["z"] = 2, ["name"] = "default:water_source" }, { ["x"] = 2, ["meta"] = { ["fields"] = {  }, ["inventory"] = {  } }, ["param2"] = 0, ["y"] = 1, ["param1"] = 13, ["z"] = 3, ["name"] = "default:water_source" }, { ["x"] = 2, ["meta"] = { ["fields"] = {  }, ["inventory"] = {  } }, ["param2"] = 0, ["y"] = 1, ["param1"] = 13, ["z"] = 4, ["name"] = "default:water_source" }, { ["x"] = 2, ["meta"] = { ["fields"] = {  }, ["inventory"] = {  } }, ["param2"] = 0, ["y"] = 1, ["param1"] = 13, ["z"] = 5, ["name"] = "default:water_source" }, { ["x"] = 2, ["meta"] = { ["fields"] = {  }, ["inventory"] = {  } }, ["param2"] = 0, ["y"] = 1, ["param1"] = 13, ["z"] = 6, ["name"] = "default:water_source" }, { ["x"] = 2, ["meta"] = { ["fields"] = {  }, ["inventory"] = {  } }, ["param2"] = 0, ["y"] = 1, ["param1"] = 0, ["z"] = 7, ["name"] = "default:junglewood" }, { ["x"] = 2, ["meta"] = { ["fields"] = {  }, ["inventory"] = {  } }, ["param2"] = 0, ["y"] = 2, ["param1"] = 15, ["z"] = 0, ["name"] = "air" }, { ["x"] = 2, ["meta"] = { ["fields"] = {  }, ["inventory"] = {  } }, ["param2"] = 3, ["y"] = 2, ["param1"] = 13, ["z"] = 1, ["name"] = "default:fence_wood" }, { ["x"] = 2, ["meta"] = { ["fields"] = {  }, ["inventory"] = {  } }, ["param2"] = 0, ["y"] = 2, ["param1"] = 15, ["z"] = 2, ["name"] = "air" }, { ["x"] = 2, ["meta"] = { ["fields"] = {  }, ["inventory"] = {  } }, ["param2"] = 0, ["y"] = 2, ["param1"] = 15, ["z"] = 3, ["name"] = "air" }, { ["x"] = 2, ["meta"] = { ["fields"] = {  }, ["inventory"] = {  } }, ["param2"] = 0, ["y"] = 2, ["param1"] = 15, ["z"] = 4, ["name"] = "air" }, { ["x"] = 2, ["meta"] = { ["fields"] = {  }, ["inventory"] = {  } }, ["param2"] = 0, ["y"] = 2, ["param1"] = 15, ["z"] = 5, ["name"] = "air" }, { ["x"] = 2, ["meta"] = { ["fields"] = {  }, ["inventory"] = {  } }, ["param2"] = 0, ["y"] = 2, ["param1"] = 15, ["z"] = 6, ["name"] = "air" }, { ["x"] = 2, ["meta"] = { ["fields"] = {  }, ["inventory"] = {  } }, ["param2"] = 3, ["y"] = 2, ["param1"] = 13, ["z"] = 7, ["name"] = "default:fence_wood" }, { ["x"] = 2, ["meta"] = { ["fields"] = {  }, ["inventory"] = {  } }, ["param2"] = 0, ["y"] = 2, ["param1"] = 15, ["z"] = 8, ["name"] = "air" }, { ["x"] = 2, ["meta"] = { ["fields"] = {  }, ["inventory"] = {  } }, ["param2"] = 0, ["y"] = 3, ["param1"] = 15, ["z"] = 0, ["name"] = "air" }, { ["x"] = 2, ["meta"] = { ["fields"] = {  }, ["inventory"] = {  } }, ["param2"] = 0, ["y"] = 3, ["param1"] = 15, ["z"] = 1, ["name"] = "air" }, { ["x"] = 2, ["meta"] = { ["fields"] = {  }, ["inventory"] = {  } }, ["param2"] = 0, ["y"] = 3, ["param1"] = 15, ["z"] = 2, ["name"] = "air" }, { ["x"] = 2, ["meta"] = { ["fields"] = {  }, ["inventory"] = {  } }, ["param2"] = 0, ["y"] = 3, ["param1"] = 15, ["z"] = 3, ["name"] = "air" }, { ["x"] = 2, ["meta"] = { ["fields"] = {  }, ["inventory"] = {  } }, ["param2"] = 0, ["y"] = 3, ["param1"] = 15, ["z"] = 4, ["name"] = "air" }, { ["x"] = 2, ["meta"] = { ["fields"] = {  }, ["inventory"] = {  } }, ["param2"] = 0, ["y"] = 3, ["param1"] = 15, ["z"] = 5, ["name"] = "air" }, { ["x"] = 2, ["meta"] = { ["fields"] = {  }, ["inventory"] = {  } }, ["param2"] = 0, ["y"] = 3, ["param1"] = 15, ["z"] = 6, ["name"] = "air" }, { ["x"] = 2, ["meta"] = { ["fields"] = {  }, ["inventory"] = {  } }, ["param2"] = 0, ["y"] = 3, ["param1"] = 15, ["z"] = 7, ["name"] = "air" }, { ["x"] = 2, ["meta"] = { ["fields"] = {  }, ["inventory"] = {  } }, ["param2"] = 0, ["y"] = 3, ["param1"] = 15, ["z"] = 8, ["name"] = "air" }, { ["x"] = 3, ["meta"] = { ["fields"] = {  }, ["inventory"] = {  } }, ["param2"] = 0, ["y"] = 0, ["param1"] = 0, ["z"] = 1, ["name"] = "default:dirt" }, { ["x"] = 3, ["meta"] = { ["fields"] = {  }, ["inventory"] = {  } }, ["param2"] = 0, ["y"] = 0, ["param1"] = 0, ["z"] = 2, ["name"] = "default:dirt" }, { ["x"] = 3, ["meta"] = { ["fields"] = {  }, ["inventory"] = {  } }, ["param2"] = 0, ["y"] = 0, ["param1"] = 0, ["z"] = 3, ["name"] = "default:dirt" }, { ["x"] = 3, ["meta"] = { ["fields"] = {  }, ["inventory"] = {  } }, ["param2"] = 0, ["y"] = 0, ["param1"] = 0, ["z"] = 4, ["name"] = "default:dirt" }, { ["x"] = 3, ["meta"] = { ["fields"] = {  }, ["inventory"] = {  } }, ["param2"] = 0, ["y"] = 0, ["param1"] = 0, ["z"] = 5, ["name"] = "default:dirt" }, { ["x"] = 3, ["meta"] = { ["fields"] = {  }, ["inventory"] = {  } }, ["param2"] = 0, ["y"] = 0, ["param1"] = 0, ["z"] = 6, ["name"] = "default:dirt" }, { ["x"] = 3, ["meta"] = { ["fields"] = {  }, ["inventory"] = {  } }, ["param2"] = 0, ["y"] = 0, ["param1"] = 0, ["z"] = 7, ["name"] = "default:dirt" }, { ["x"] = 3, ["meta"] = { ["fields"] = {  }, ["inventory"] = {  } }, ["param2"] = 0, ["y"] = 1, ["param1"] = 0, ["z"] = 1, ["name"] = "default:junglewood" }, { ["x"] = 3, ["meta"] = { ["fields"] = {  }, ["inventory"] = {  } }, ["param2"] = 0, ["y"] = 1, ["param1"] = 0, ["z"] = 2, ["name"] = "default:dirt_with_grass" }, { ["x"] = 3, ["meta"] = { ["fields"] = {  }, ["inventory"] = {  } }, ["param2"] = 0, ["y"] = 1, ["param1"] = 0, ["z"] = 3, ["name"] = "default:dirt_with_grass" }, { ["x"] = 3, ["meta"] = { ["fields"] = {  }, ["inventory"] = {  } }, ["param2"] = 0, ["y"] = 1, ["param1"] = 0, ["z"] = 4, ["name"] = "default:dirt_with_grass" }, { ["x"] = 3, ["meta"] = { ["fields"] = {  }, ["inventory"] = {  } }, ["param2"] = 0, ["y"] = 1, ["param1"] = 0, ["z"] = 5, ["name"] = "default:dirt_with_grass" }, { ["x"] = 3, ["meta"] = { ["fields"] = {  }, ["inventory"] = {  } }, ["param2"] = 0, ["y"] = 1, ["param1"] = 0, ["z"] = 6, ["name"] = "default:dirt_with_grass" }, { ["x"] = 3, ["meta"] = { ["fields"] = {  }, ["inventory"] = {  } }, ["param2"] = 0, ["y"] = 1, ["param1"] = 0, ["z"] = 7, ["name"] = "default:junglewood" }, { ["x"] = 3, ["meta"] = { ["fields"] = {  }, ["inventory"] = {  } }, ["param2"] = 0, ["y"] = 2, ["param1"] = 15, ["z"] = 0, ["name"] = "air" }, { ["x"] = 3, ["meta"] = { ["fields"] = {  }, ["inventory"] = {  } }, ["param2"] = 3, ["y"] = 2, ["param1"] = 13, ["z"] = 1, ["name"] = "default:fence_wood" }, { ["x"] = 3, ["meta"] = { ["fields"] = {  }, ["inventory"] = {  } }, ["param2"] = 0, ["y"] = 2, ["param1"] = 13, ["z"] = 2, ["name"] = "default:papyrus" }, { ["x"] = 3, ["meta"] = { ["fields"] = {  }, ["inventory"] = {  } }, ["param2"] = 0, ["y"] = 2, ["param1"] = 13, ["z"] = 3, ["name"] = "default:papyrus" }, { ["x"] = 3, ["meta"] = { ["fields"] = {  }, ["inventory"] = {  } }, ["param2"] = 0, ["y"] = 2, ["param1"] = 13, ["z"] = 4, ["name"] = "default:papyrus" }, { ["x"] = 3, ["meta"] = { ["fields"] = {  }, ["inventory"] = {  } }, ["param2"] = 0, ["y"] = 2, ["param1"] = 13, ["z"] = 5, ["name"] = "default:papyrus" }, { ["x"] = 3, ["meta"] = { ["fields"] = {  }, ["inventory"] = {  } }, ["param2"] = 0, ["y"] = 2, ["param1"] = 13, ["z"] = 6, ["name"] = "default:papyrus" }, { ["x"] = 3, ["meta"] = { ["fields"] = {  }, ["inventory"] = {  } }, ["param2"] = 3, ["y"] = 2, ["param1"] = 13, ["z"] = 7, ["name"] = "default:fence_wood" }, { ["x"] = 3, ["meta"] = { ["fields"] = {  }, ["inventory"] = {  } }, ["param2"] = 0, ["y"] = 2, ["param1"] = 15, ["z"] = 8, ["name"] = "air" }, { ["x"] = 3, ["meta"] = { ["fields"] = {  }, ["inventory"] = {  } }, ["param2"] = 0, ["y"] = 3, ["param1"] = 15, ["z"] = 0, ["name"] = "air" }, { ["x"] = 3, ["meta"] = { ["fields"] = {  }, ["inventory"] = {  } }, ["param2"] = 0, ["y"] = 3, ["param1"] = 15, ["z"] = 1, ["name"] = "air" }, { ["x"] = 3, ["meta"] = { ["fields"] = {  }, ["inventory"] = {  } }, ["param2"] = 0, ["y"] = 3, ["param1"] = 15, ["z"] = 2, ["name"] = "air" }, { ["x"] = 3, ["meta"] = { ["fields"] = {  }, ["inventory"] = {  } }, ["param2"] = 0, ["y"] = 3, ["param1"] = 15, ["z"] = 3, ["name"] = "air" }, { ["x"] = 3, ["meta"] = { ["fields"] = {  }, ["inventory"] = {  } }, ["param2"] = 0, ["y"] = 3, ["param1"] = 15, ["z"] = 4, ["name"] = "air" }, { ["x"] = 3, ["meta"] = { ["fields"] = {  }, ["inventory"] = {  } }, ["param2"] = 0, ["y"] = 3, ["param1"] = 15, ["z"] = 5, ["name"] = "air" }, { ["x"] = 3, ["meta"] = { ["fields"] = {  }, ["inventory"] = {  } }, ["param2"] = 0, ["y"] = 3, ["param1"] = 15, ["z"] = 6, ["name"] = "air" }, { ["x"] = 3, ["meta"] = { ["fields"] = {  }, ["inventory"] = {  } }, ["param2"] = 0, ["y"] = 3, ["param1"] = 15, ["z"] = 7, ["name"] = "air" }, { ["x"] = 3, ["meta"] = { ["fields"] = {  }, ["inventory"] = {  } }, ["param2"] = 0, ["y"] = 3, ["param1"] = 15, ["z"] = 8, ["name"] = "air" }, { ["x"] = 4, ["meta"] = { ["fields"] = {  }, ["inventory"] = {  } }, ["param2"] = 0, ["y"] = 0, ["param1"] = 0, ["z"] = 1, ["name"] = "default:dirt" }, { ["x"] = 4, ["meta"] = { ["fields"] = {  }, ["inventory"] = {  } }, ["param2"] = 0, ["y"] = 0, ["param1"] = 0, ["z"] = 2, ["name"] = "default:dirt" }, { ["x"] = 4, ["meta"] = { ["fields"] = {  }, ["inventory"] = {  } }, ["param2"] = 0, ["y"] = 0, ["param1"] = 0, ["z"] = 3, ["name"] = "default:dirt" }, { ["x"] = 4, ["meta"] = { ["fields"] = {  }, ["inventory"] = {  } }, ["param2"] = 0, ["y"] = 0, ["param1"] = 0, ["z"] = 4, ["name"] = "default:dirt" }, { ["x"] = 4, ["meta"] = { ["fields"] = {  }, ["inventory"] = {  } }, ["param2"] = 0, ["y"] = 0, ["param1"] = 0, ["z"] = 5, ["name"] = "default:dirt" }, { ["x"] = 4, ["meta"] = { ["fields"] = {  }, ["inventory"] = {  } }, ["param2"] = 0, ["y"] = 0, ["param1"] = 0, ["z"] = 6, ["name"] = "default:dirt" }, { ["x"] = 4, ["meta"] = { ["fields"] = {  }, ["inventory"] = {  } }, ["param2"] = 0, ["y"] = 0, ["param1"] = 0, ["z"] = 7, ["name"] = "default:dirt" }, { ["x"] = 4, ["meta"] = { ["fields"] = {  }, ["inventory"] = {  } }, ["param2"] = 0, ["y"] = 1, ["param1"] = 0, ["z"] = 1, ["name"] = "default:junglewood" }, { ["x"] = 4, ["meta"] = { ["fields"] = {  }, ["inventory"] = {  } }, ["param2"] = 0, ["y"] = 1, ["param1"] = 0, ["z"] = 2, ["name"] = "farming:soil_wet" }, { ["x"] = 4, ["meta"] = { ["fields"] = {  }, ["inventory"] = {  } }, ["param2"] = 0, ["y"] = 1, ["param1"] = 0, ["z"] = 3, ["name"] = "farming:soil_wet" }, { ["x"] = 4, ["meta"] = { ["fields"] = {  }, ["inventory"] = {  } }, ["param2"] = 0, ["y"] = 1, ["param1"] = 0, ["z"] = 4, ["name"] = "farming:soil_wet" }, { ["x"] = 4, ["meta"] = { ["fields"] = {  }, ["inventory"] = {  } }, ["param2"] = 0, ["y"] = 1, ["param1"] = 0, ["z"] = 5, ["name"] = "farming:soil_wet" }, { ["x"] = 4, ["meta"] = { ["fields"] = {  }, ["inventory"] = {  } }, ["param2"] = 0, ["y"] = 1, ["param1"] = 0, ["z"] = 6, ["name"] = "farming:soil_wet" }, { ["x"] = 4, ["meta"] = { ["fields"] = {  }, ["inventory"] = {  } }, ["param2"] = 0, ["y"] = 1, ["param1"] = 0, ["z"] = 7, ["name"] = "default:junglewood" }, { ["x"] = 4, ["meta"] = { ["fields"] = {  }, ["inventory"] = {  } }, ["param2"] = 0, ["y"] = 2, ["param1"] = 15, ["z"] = 0, ["name"] = "air" }, { ["x"] = 4, ["meta"] = { ["fields"] = {  }, ["inventory"] = {  } }, ["param2"] = 3, ["y"] = 2, ["param1"] = 13, ["z"] = 1, ["name"] = "default:fence_wood" }, { ["x"] = 4, ["meta"] = { ["fields"] = {  }, ["inventory"] = {  } }, ["param2"] = 0, ["y"] = 2, ["param1"] = 13, ["z"] = 2, ["name"] = "farming_plus:potatoe_1" }, { ["x"] = 4, ["meta"] = { ["fields"] = {  }, ["inventory"] = {  } }, ["param2"] = 0, ["y"] = 2, ["param1"] = 13, ["z"] = 3, ["name"] = "farming_plus:potatoe_1" }, { ["x"] = 4, ["meta"] = { ["fields"] = {  }, ["inventory"] = {  } }, ["param2"] = 0, ["y"] = 2, ["param1"] = 13, ["z"] = 4, ["name"] = "farming_plus:potatoe_1" }, { ["x"] = 4, ["meta"] = { ["fields"] = {  }, ["inventory"] = {  } }, ["param2"] = 0, ["y"] = 2, ["param1"] = 13, ["z"] = 5, ["name"] = "farming_plus:potatoe_1" }, { ["x"] = 4, ["meta"] = { ["fields"] = {  }, ["inventory"] = {  } }, ["param2"] = 0, ["y"] = 2, ["param1"] = 13, ["z"] = 6, ["name"] = "farming_plus:potatoe_1" }, { ["x"] = 4, ["meta"] = { ["fields"] = {  }, ["inventory"] = {  } }, ["param2"] = 3, ["y"] = 2, ["param1"] = 13, ["z"] = 7, ["name"] = "default:fence_wood" }, { ["x"] = 4, ["meta"] = { ["fields"] = {  }, ["inventory"] = {  } }, ["param2"] = 0, ["y"] = 2, ["param1"] = 15, ["z"] = 8, ["name"] = "air" }, { ["x"] = 4, ["meta"] = { ["fields"] = {  }, ["inventory"] = {  } }, ["param2"] = 0, ["y"] = 3, ["param1"] = 15, ["z"] = 0, ["name"] = "air" }, { ["x"] = 4, ["meta"] = { ["fields"] = {  }, ["inventory"] = {  } }, ["param2"] = 0, ["y"] = 3, ["param1"] = 15, ["z"] = 1, ["name"] = "air" }, { ["x"] = 4, ["meta"] = { ["fields"] = {  }, ["inventory"] = {  } }, ["param2"] = 0, ["y"] = 3, ["param1"] = 15, ["z"] = 2, ["name"] = "air" }, { ["x"] = 4, ["meta"] = { ["fields"] = {  }, ["inventory"] = {  } }, ["param2"] = 0, ["y"] = 3, ["param1"] = 31, ["z"] = 3, ["name"] = "air" }, { ["x"] = 4, ["meta"] = { ["fields"] = {  }, ["inventory"] = {  } }, ["param2"] = 0, ["y"] = 3, ["param1"] = 15, ["z"] = 4, ["name"] = "air" }, { ["x"] = 4, ["meta"] = { ["fields"] = {  }, ["inventory"] = {  } }, ["param2"] = 0, ["y"] = 3, ["param1"] = 15, ["z"] = 5, ["name"] = "air" }, { ["x"] = 4, ["meta"] = { ["fields"] = {  }, ["inventory"] = {  } }, ["param2"] = 0, ["y"] = 3, ["param1"] = 15, ["z"] = 6, ["name"] = "air" }, { ["x"] = 4, ["meta"] = { ["fields"] = {  }, ["inventory"] = {  } }, ["param2"] = 0, ["y"] = 3, ["param1"] = 15, ["z"] = 7, ["name"] = "air" }, { ["x"] = 4, ["meta"] = { ["fields"] = {  }, ["inventory"] = {  } }, ["param2"] = 0, ["y"] = 3, ["param1"] = 15, ["z"] = 8, ["name"] = "air" }, { ["x"] = 5, ["meta"] = { ["fields"] = {  }, ["inventory"] = {  } }, ["param2"] = 0, ["y"] = 0, ["param1"] = 0, ["z"] = 1, ["name"] = "default:dirt" }, { ["x"] = 5, ["meta"] = { ["fields"] = {  }, ["inventory"] = {  } }, ["param2"] = 0, ["y"] = 0, ["param1"] = 0, ["z"] = 2, ["name"] = "default:dirt" }, { ["x"] = 5, ["meta"] = { ["fields"] = {  }, ["inventory"] = {  } }, ["param2"] = 0, ["y"] = 0, ["param1"] = 0, ["z"] = 3, ["name"] = "default:dirt" }, { ["x"] = 5, ["meta"] = { ["fields"] = {  }, ["inventory"] = {  } }, ["param2"] = 0, ["y"] = 0, ["param1"] = 0, ["z"] = 4, ["name"] = "default:dirt" }, { ["x"] = 5, ["meta"] = { ["fields"] = {  }, ["inventory"] = {  } }, ["param2"] = 0, ["y"] = 0, ["param1"] = 0, ["z"] = 5, ["name"] = "default:dirt" }, { ["x"] = 5, ["meta"] = { ["fields"] = {  }, ["inventory"] = {  } }, ["param2"] = 0, ["y"] = 0, ["param1"] = 0, ["z"] = 6, ["name"] = "default:dirt" }, { ["x"] = 5, ["meta"] = { ["fields"] = {  }, ["inventory"] = {  } }, ["param2"] = 0, ["y"] = 0, ["param1"] = 0, ["z"] = 7, ["name"] = "default:dirt" }, { ["x"] = 5, ["meta"] = { ["fields"] = {  }, ["inventory"] = {  } }, ["param2"] = 0, ["y"] = 1, ["param1"] = 0, ["z"] = 1, ["name"] = "default:junglewood" }, { ["x"] = 5, ["meta"] = { ["fields"] = {  }, ["inventory"] = {  } }, ["param2"] = 0, ["y"] = 1, ["param1"] = 0, ["z"] = 2, ["name"] = "farming:soil_wet" }, { ["x"] = 5, ["meta"] = { ["fields"] = {  }, ["inventory"] = {  } }, ["param2"] = 0, ["y"] = 1, ["param1"] = 0, ["z"] = 3, ["name"] = "farming:soil_wet" }, { ["x"] = 5, ["meta"] = { ["fields"] = {  }, ["inventory"] = {  } }, ["param2"] = 0, ["y"] = 1, ["param1"] = 0, ["z"] = 4, ["name"] = "farming:soil_wet" }, { ["x"] = 5, ["meta"] = { ["fields"] = {  }, ["inventory"] = {  } }, ["param2"] = 0, ["y"] = 1, ["param1"] = 0, ["z"] = 5, ["name"] = "farming:soil_wet" }, { ["x"] = 5, ["meta"] = { ["fields"] = {  }, ["inventory"] = {  } }, ["param2"] = 0, ["y"] = 1, ["param1"] = 0, ["z"] = 6, ["name"] = "farming:soil_wet" }, { ["x"] = 5, ["meta"] = { ["fields"] = {  }, ["inventory"] = {  } }, ["param2"] = 0, ["y"] = 1, ["param1"] = 0, ["z"] = 7, ["name"] = "default:junglewood" }, { ["x"] = 5, ["meta"] = { ["fields"] = {  }, ["inventory"] = {  } }, ["param2"] = 0, ["y"] = 2, ["param1"] = 15, ["z"] = 0, ["name"] = "air" }, { ["x"] = 5, ["meta"] = { ["fields"] = {  }, ["inventory"] = {  } }, ["param2"] = 3, ["y"] = 2, ["param1"] = 13, ["z"] = 1, ["name"] = "default:fence_wood" }, { ["x"] = 5, ["meta"] = { ["fields"] = {  }, ["inventory"] = {  } }, ["param2"] = 0, ["y"] = 2, ["param1"] = 13, ["z"] = 2, ["name"] = "farming_plus:potatoe_1" }, { ["x"] = 5, ["meta"] = { ["fields"] = {  }, ["inventory"] = {  } }, ["param2"] = 0, ["y"] = 2, ["param1"] = 29, ["z"] = 3, ["name"] = "farming_plus:potatoe_1" }, { ["x"] = 5, ["meta"] = { ["fields"] = {  }, ["inventory"] = {  } }, ["param2"] = 0, ["y"] = 2, ["param1"] = 13, ["z"] = 4, ["name"] = "farming_plus:potatoe_1" }, { ["x"] = 5, ["meta"] = { ["fields"] = {  }, ["inventory"] = {  } }, ["param2"] = 0, ["y"] = 2, ["param1"] = 13, ["z"] = 5, ["name"] = "farming_plus:potatoe_1" }, { ["x"] = 5, ["meta"] = { ["fields"] = {  }, ["inventory"] = {  } }, ["param2"] = 0, ["y"] = 2, ["param1"] = 13, ["z"] = 6, ["name"] = "farming_plus:potatoe_1" }, { ["x"] = 5, ["meta"] = { ["fields"] = {  }, ["inventory"] = {  } }, ["param2"] = 3, ["y"] = 2, ["param1"] = 13, ["z"] = 7, ["name"] = "default:fence_wood" }, { ["x"] = 5, ["meta"] = { ["fields"] = {  }, ["inventory"] = {  } }, ["param2"] = 0, ["y"] = 2, ["param1"] = 15, ["z"] = 8, ["name"] = "air" }, { ["x"] = 5, ["meta"] = { ["fields"] = {  }, ["inventory"] = {  } }, ["param2"] = 0, ["y"] = 3, ["param1"] = 31, ["z"] = 0, ["name"] = "air" }, { ["x"] = 5, ["meta"] = { ["fields"] = {  }, ["inventory"] = {  } }, ["param2"] = 0, ["y"] = 3, ["param1"] = 15, ["z"] = 1, ["name"] = "air" }, { ["x"] = 5, ["meta"] = { ["fields"] = {  }, ["inventory"] = {  } }, ["param2"] = 0, ["y"] = 3, ["param1"] = 31, ["z"] = 2, ["name"] = "air" }, { ["x"] = 5, ["meta"] = { ["fields"] = {  }, ["inventory"] = {  } }, ["param2"] = 0, ["y"] = 3, ["param1"] = 47, ["z"] = 3, ["name"] = "air" }, { ["x"] = 5, ["meta"] = { ["fields"] = {  }, ["inventory"] = {  } }, ["param2"] = 0, ["y"] = 3, ["param1"] = 31, ["z"] = 4, ["name"] = "air" }, { ["x"] = 5, ["meta"] = { ["fields"] = {  }, ["inventory"] = {  } }, ["param2"] = 0, ["y"] = 3, ["param1"] = 15, ["z"] = 5, ["name"] = "air" }, { ["x"] = 5, ["meta"] = { ["fields"] = {  }, ["inventory"] = {  } }, ["param2"] = 0, ["y"] = 3, ["param1"] = 15, ["z"] = 6, ["name"] = "air" }, { ["x"] = 5, ["meta"] = { ["fields"] = {  }, ["inventory"] = {  } }, ["param2"] = 0, ["y"] = 3, ["param1"] = 15, ["z"] = 7, ["name"] = "air" }, { ["x"] = 5, ["meta"] = { ["fields"] = {  }, ["inventory"] = {  } }, ["param2"] = 0, ["y"] = 3, ["param1"] = 15, ["z"] = 8, ["name"] = "air" }, { ["x"] = 6, ["meta"] = { ["fields"] = {  }, ["inventory"] = {  } }, ["param2"] = 0, ["y"] = 0, ["param1"] = 0, ["z"] = 1, ["name"] = "default:dirt" }, { ["x"] = 6, ["meta"] = { ["fields"] = {  }, ["inventory"] = {  } }, ["param2"] = 0, ["y"] = 0, ["param1"] = 0, ["z"] = 2, ["name"] = "default:dirt" }, { ["x"] = 6, ["meta"] = { ["fields"] = {  }, ["inventory"] = {  } }, ["param2"] = 0, ["y"] = 0, ["param1"] = 0, ["z"] = 3, ["name"] = "default:dirt" }, { ["x"] = 6, ["meta"] = { ["fields"] = {  }, ["inventory"] = {  } }, ["param2"] = 0, ["y"] = 0, ["param1"] = 0, ["z"] = 4, ["name"] = "default:dirt" }, { ["x"] = 6, ["meta"] = { ["fields"] = {  }, ["inventory"] = {  } }, ["param2"] = 0, ["y"] = 0, ["param1"] = 0, ["z"] = 5, ["name"] = "default:dirt" }, { ["x"] = 6, ["meta"] = { ["fields"] = {  }, ["inventory"] = {  } }, ["param2"] = 0, ["y"] = 0, ["param1"] = 0, ["z"] = 6, ["name"] = "default:dirt" }, { ["x"] = 6, ["meta"] = { ["fields"] = {  }, ["inventory"] = {  } }, ["param2"] = 0, ["y"] = 0, ["param1"] = 0, ["z"] = 7, ["name"] = "default:dirt" }, { ["x"] = 6, ["meta"] = { ["fields"] = {  }, ["inventory"] = {  } }, ["param2"] = 0, ["y"] = 1, ["param1"] = 0, ["z"] = 1, ["name"] = "default:junglewood" }, { ["x"] = 6, ["meta"] = { ["fields"] = {  }, ["inventory"] = {  } }, ["param2"] = 0, ["y"] = 1, ["param1"] = 0, ["z"] = 2, ["name"] = "default:junglewood" }, { ["x"] = 6, ["meta"] = { ["fields"] = {  }, ["inventory"] = {  } }, ["param2"] = 0, ["y"] = 1, ["param1"] = 0, ["z"] = 3, ["name"] = "default:junglewood" }, { ["x"] = 6, ["meta"] = { ["fields"] = {  }, ["inventory"] = {  } }, ["param2"] = 0, ["y"] = 1, ["param1"] = 0, ["z"] = 4, ["name"] = "default:junglewood" }, { ["x"] = 6, ["meta"] = { ["fields"] = {  }, ["inventory"] = {  } }, ["param2"] = 0, ["y"] = 1, ["param1"] = 0, ["z"] = 5, ["name"] = "default:junglewood" }, { ["x"] = 6, ["meta"] = { ["fields"] = {  }, ["inventory"] = {  } }, ["param2"] = 0, ["y"] = 1, ["param1"] = 0, ["z"] = 6, ["name"] = "default:junglewood" }, { ["x"] = 6, ["meta"] = { ["fields"] = {  }, ["inventory"] = {  } }, ["param2"] = 0, ["y"] = 1, ["param1"] = 0, ["z"] = 7, ["name"] = "default:junglewood" }, { ["x"] = 6, ["meta"] = { ["fields"] = {  }, ["inventory"] = {  } }, ["param2"] = 0, ["y"] = 2, ["param1"] = 31, ["z"] = 0, ["name"] = "air" }, { ["x"] = 6, ["meta"] = { ["fields"] = {  }, ["inventory"] = {  } }, ["param2"] = 3, ["y"] = 2, ["param1"] = 13, ["z"] = 1, ["name"] = "default:fence_wood" }, { ["x"] = 6, ["meta"] = { ["fields"] = {  }, ["inventory"] = {  } }, ["param2"] = 3, ["y"] = 2, ["param1"] = 29, ["z"] = 2, ["name"] = "default:fence_wood" }, { ["x"] = 6, ["meta"] = { ["fields"] = {  }, ["inventory"] = {  } }, ["param2"] = 3, ["y"] = 2, ["param1"] = 45, ["z"] = 3, ["name"] = "default:fence_wood" }, { ["x"] = 6, ["meta"] = { ["fields"] = {  }, ["inventory"] = {  } }, ["param2"] = 0, ["y"] = 2, ["param1"] = 31, ["z"] = 4, ["name"] = "air" }, { ["x"] = 6, ["meta"] = { ["fields"] = {  }, ["inventory"] = {  } }, ["param2"] = 3, ["y"] = 2, ["param1"] = 13, ["z"] = 5, ["name"] = "default:fence_wood" }, { ["x"] = 6, ["meta"] = { ["fields"] = {  }, ["inventory"] = {  } }, ["param2"] = 0, ["y"] = 2, ["param1"] = 13, ["z"] = 6, ["name"] = "default:fence_wood" }, { ["x"] = 6, ["meta"] = { ["fields"] = {  }, ["inventory"] = {  } }, ["param2"] = 3, ["y"] = 2, ["param1"] = 13, ["z"] = 7, ["name"] = "default:fence_wood" }, { ["x"] = 6, ["meta"] = { ["fields"] = {  }, ["inventory"] = {  } }, ["param2"] = 0, ["y"] = 2, ["param1"] = 15, ["z"] = 8, ["name"] = "air" }, { ["x"] = 6, ["meta"] = { ["fields"] = {  }, ["inventory"] = {  } }, ["param2"] = 0, ["y"] = 3, ["param1"] = 47, ["z"] = 0, ["name"] = "air" }, { ["x"] = 6, ["meta"] = { ["fields"] = {  }, ["inventory"] = {  } }, ["param2"] = 0, ["y"] = 3, ["param1"] = 31, ["z"] = 1, ["name"] = "air" }, { ["x"] = 6, ["meta"] = { ["fields"] = {  }, ["inventory"] = {  } }, ["param2"] = 0, ["y"] = 3, ["param1"] = 47, ["z"] = 2, ["name"] = "air" }, { ["x"] = 6, ["meta"] = { ["fields"] = {  }, ["inventory"] = {  } }, ["param2"] = 0, ["y"] = 3, ["param1"] = 63, ["z"] = 3, ["name"] = "air" }, { ["x"] = 6, ["meta"] = { ["fields"] = {  }, ["inventory"] = {  } }, ["param2"] = 0, ["y"] = 3, ["param1"] = 47, ["z"] = 4, ["name"] = "air" }, { ["x"] = 6, ["meta"] = { ["fields"] = {  }, ["inventory"] = {  } }, ["param2"] = 0, ["y"] = 3, ["param1"] = 31, ["z"] = 5, ["name"] = "air" }, { ["x"] = 6, ["meta"] = { ["fields"] = {  }, ["inventory"] = {  } }, ["param2"] = 0, ["y"] = 3, ["param1"] = 15, ["z"] = 6, ["name"] = "air" }, { ["x"] = 6, ["meta"] = { ["fields"] = {  }, ["inventory"] = {  } }, ["param2"] = 0, ["y"] = 3, ["param1"] = 15, ["z"] = 7, ["name"] = "air" }, { ["x"] = 6, ["meta"] = { ["fields"] = {  }, ["inventory"] = {  } }, ["param2"] = 0, ["y"] = 3, ["param1"] = 15, ["z"] = 8, ["name"] = "air" }, { ["x"] = 7, ["meta"] = { ["fields"] = {  }, ["inventory"] = {  } }, ["param2"] = 0, ["y"] = 2, ["param1"] = 47, ["z"] = 0, ["name"] = "air" }, { ["x"] = 7, ["meta"] = { ["fields"] = {  }, ["inventory"] = {  } }, ["param2"] = 0, ["y"] = 2, ["param1"] = 31, ["z"] = 1, ["name"] = "air" }, { ["x"] = 7, ["meta"] = { ["fields"] = {  }, ["inventory"] = {  } }, ["param2"] = 0, ["y"] = 2, ["param1"] = 47, ["z"] = 2, ["name"] = "air" }, { ["x"] = 7, ["meta"] = { ["fields"] = {  }, ["inventory"] = {  } }, ["param2"] = 0, ["y"] = 2, ["param1"] = 63, ["z"] = 3, ["name"] = "air" }, { ["x"] = 7, ["meta"] = { ["fields"] = {  }, ["inventory"] = {  } }, ["param2"] = 0, ["y"] = 2, ["param1"] = 47, ["z"] = 4, ["name"] = "air" }, { ["x"] = 7, ["meta"] = { ["fields"] = {  }, ["inventory"] = {  } }, ["param2"] = 0, ["y"] = 2, ["param1"] = 31, ["z"] = 5, ["name"] = "air" }, { ["x"] = 7, ["meta"] = { ["fields"] = {  }, ["inventory"] = {  } }, ["param2"] = 0, ["y"] = 2, ["param1"] = 15, ["z"] = 6, ["name"] = "air" }, { ["x"] = 7, ["meta"] = { ["fields"] = {  }, ["inventory"] = {  } }, ["param2"] = 0, ["y"] = 2, ["param1"] = 15, ["z"] = 7, ["name"] = "air" }, { ["x"] = 7, ["meta"] = { ["fields"] = {  }, ["inventory"] = {  } }, ["param2"] = 0, ["y"] = 2, ["param1"] = 15, ["z"] = 8, ["name"] = "air" }, { ["x"] = 7, ["meta"] = { ["fields"] = {  }, ["inventory"] = {  } }, ["param2"] = 0, ["y"] = 3, ["param1"] = 63, ["z"] = 0, ["name"] = "air" }, { ["x"] = 7, ["meta"] = { ["fields"] = {  }, ["inventory"] = {  } }, ["param2"] = 0, ["y"] = 3, ["param1"] = 47, ["z"] = 1, ["name"] = "air" }, { ["x"] = 7, ["meta"] = { ["fields"] = {  }, ["inventory"] = {  } }, ["param2"] = 0, ["y"] = 3, ["param1"] = 63, ["z"] = 2, ["name"] = "air" }, { ["x"] = 7, ["meta"] = { ["fields"] = {  }, ["inventory"] = {  } }, ["param2"] = 0, ["y"] = 3, ["param1"] = 79, ["z"] = 3, ["name"] = "air" }, { ["x"] = 7, ["meta"] = { ["fields"] = {  }, ["inventory"] = {  } }, ["param2"] = 0, ["y"] = 3, ["param1"] = 63, ["z"] = 4, ["name"] = "air" }, { ["x"] = 7, ["meta"] = { ["fields"] = {  }, ["inventory"] = {  } }, ["param2"] = 0, ["y"] = 3, ["param1"] = 47, ["z"] = 5, ["name"] = "air" }, { ["x"] = 7, ["meta"] = { ["fields"] = {  }, ["inventory"] = {  } }, ["param2"] = 0, ["y"] = 3, ["param1"] = 31, ["z"] = 6, ["name"] = "air" }, { ["x"] = 7, ["meta"] = { ["fields"] = {  }, ["inventory"] = {  } }, ["param2"] = 0, ["y"] = 3, ["param1"] = 15, ["z"] = 7, ["name"] = "air" }, { ["x"] = 7, ["meta"] = { ["fields"] = {  }, ["inventory"] = {  } }, ["param2"] = 0, ["y"] = 3, ["param1"] = 15, ["z"] = 8, ["name"] = "air" } }